/**
 * Unit tests for ErrorMessage component logic
 */

import { beforeEach, describe, it } from "@std/testing/bdd";
import { assertEquals, assertExists } from "@std/assert";
import "../../test-utils/setup.ts";

describe("ErrorMessage Component Logic", () => {
  let mockOnRetry: () => Promise<void>;
  let mockOnDismiss: () => void;
  let retryCalls: number;
  let dismissCalls: number;

  beforeEach(() => {
    retryCalls = 0;
    dismissCalls = 0;
    mockOnRetry = () => {
      retryCalls++;
      return Promise.resolve();
    };
    mockOnDismiss = () => {
      dismissCalls++;
    };
  });

  it("should handle error message display logic", () => {
    const errorText = "Something went wrong";

    assertExists(errorText);
    assertEquals(typeof errorText, "string");
    assertEquals(errorText.length > 0, true);
  });

  it("should handle button visibility logic", () => {
    const hasRetryCallback = mockOnRetry !== undefined;
    const hasDismissCallback = mockOnDismiss !== undefined;

    assertEquals(hasRetryCallback, true);
    assertEquals(hasDismissCallback, true);

    // When no callbacks provided
    const noRetry = undefined;
    const noDismiss = undefined;

    assertEquals(noRetry === undefined, true);
    assertEquals(noDismiss === undefined, true);
  });

  it("should handle retry functionality", async () => {
    // Simulate retry button click
    await mockOnRetry();

    assertEquals(retryCalls, 1);
  });

  it("should handle dismiss functionality", () => {
    // Simulate dismiss button click
    mockOnDismiss();

    assertEquals(dismissCalls, 1);
  });

  it("should handle multiple retry attempts", async () => {
    // Simulate multiple retry clicks
    await mockOnRetry();
    await mockOnRetry();
    await mockOnRetry();

    assertEquals(retryCalls, 3);
  });

  it("should handle error message types", () => {
    const networkError = "Network connection failed";
    const apiError = "API rate limit exceeded";
    const validationError = "Invalid input provided";

    // All should be valid error messages
    [networkError, apiError, validationError].forEach((error) => {
      assertExists(error);
      assertEquals(typeof error, "string");
      assertEquals(error.length > 0, true);
    });
  });

  it("should handle long error messages", () => {
    const longError =
      "This is a very long error message that should wrap properly and maintain readability even when it contains multiple sentences and detailed information about what went wrong.";

    assertEquals(longError.length > 100, true);
    assertEquals(typeof longError, "string");
  });

  it("should handle special characters in error messages", () => {
    const specialError =
      "Error: <script>alert('xss')</script> & \"quotes\" & 'apostrophes'";

    assertExists(specialError);
    assertEquals(specialError.includes("<"), true);
    assertEquals(specialError.includes("&"), true);
    assertEquals(specialError.includes('"'), true);
  });

  it("should handle empty error message", () => {
    const emptyError = "";

    assertEquals(emptyError, "");
    assertEquals(emptyError.length, 0);

    // Should still show error container even with empty message
    const hasError = true; // Error state exists even if message is empty
    assertEquals(hasError, true);
  });

  it("should handle multiline error messages", () => {
    const multilineError = "Error occurred:\nLine 1\nLine 2\nLine 3";

    assertEquals(multilineError.includes("\n"), true);
    assertEquals(multilineError.split("\n").length, 4);
  });

  it("should handle error severity levels", () => {
    const infoError = "Information: Operation completed with warnings";
    const warningError = "Warning: Deprecated API usage detected";
    const criticalError = "Critical: System failure detected";

    // Classify error severity based on prefix
    const getErrorSeverity = (error: string) => {
      if (error.startsWith("Critical:")) return "critical";
      if (error.startsWith("Warning:")) return "warning";
      if (error.startsWith("Information:")) return "info";
      return "error";
    };

    assertEquals(getErrorSeverity(infoError), "info");
    assertEquals(getErrorSeverity(warningError), "warning");
    assertEquals(getErrorSeverity(criticalError), "critical");
  });

  it("should handle rapid button interactions", async () => {
    // Simulate rapid retry and dismiss clicks
    await mockOnRetry();
    mockOnDismiss();
    await mockOnRetry();
    mockOnDismiss();

    assertEquals(retryCalls, 2);
    assertEquals(dismissCalls, 2);
  });

  it("should handle async retry errors", async () => {
    let retryError = false;

    const errorRetry = () => {
      retryError = true;
      return Promise.reject(new Error("Retry failed"));
    };

    try {
      await errorRetry();
    } catch {
      // Error should be caught and handled gracefully
    }

    assertEquals(retryError, true);
  });

  it("should handle error state management", () => {
    let hasError = false;
    let errorMessage = "";

    // Set error state
    hasError = true;
    errorMessage = "Test error";

    assertEquals(hasError, true);
    assertEquals(errorMessage, "Test error");

    // Clear error state (dismiss)
    hasError = false;
    errorMessage = "";

    assertEquals(hasError, false);
    assertEquals(errorMessage, "");
  });

  it("should handle error persistence logic", () => {
    let errorCount = 0;
    let shouldPersist = false;

    // Increment error count
    errorCount++;

    // Persist error if it occurs multiple times
    if (errorCount > 2) {
      shouldPersist = true;
    }

    assertEquals(errorCount, 1);
    assertEquals(shouldPersist, false);

    // Simulate more errors
    errorCount += 2;
    if (errorCount > 2) {
      shouldPersist = true;
    }

    assertEquals(errorCount, 3);
    assertEquals(shouldPersist, true);
  });

  it("should handle error formatting logic", () => {
    const rawError = "  ERROR: Something went wrong  ";

    // Clean and format error message
    const cleanError = rawError.trim();
    const formattedError = cleanError.replace(/^ERROR:\s*/, "");

    assertEquals(cleanError, "ERROR: Something went wrong");
    assertEquals(formattedError, "Something went wrong");
  });

  it("should handle error context information", () => {
    const errorContext = {
      timestamp: new Date(),
      component: "ErrorMessage",
      action: "retry",
      attempt: 1,
    };

    assertExists(errorContext.timestamp);
    assertEquals(errorContext.component, "ErrorMessage");
    assertEquals(errorContext.action, "retry");
    assertEquals(errorContext.attempt, 1);
  });
});
